Workbook

Sheet ICT Projects - Consolidated
A1: Region | B1: Project ID | C1: Project / Scheme Name | D1: Sector / Division | E1: Sub-Sector | F1: Ministry / Department / Authority | G1: Location | H1: Status | I1: Total Project Cost (M PKR) | J1: FY2026-27 Allocation (M PKR) | K1: ICT Involvement % | L1: ICT Level / Category | M1: ICT TAM on Allocation (M PKR) | N1: ICT TAM on Total Cost (M PKR) | O1: ICT Reasoning | P1: Fixed Connectivity | Q1: GSM / Devices | R1: Cloud | S1: Cyber Security | T1: Servers / Internet | U1: Fiber / Broadband | V1: CCTV Camera | W1: IoT | X1: SIMs (GSM/CMT) | Y1: SMS / Messaging | Z1: Source File | AA1: Source Sheet
A2: KPK (Provincial ADP) | B2: 190219 | C2: Khyber Pakhtunkhwa Cities Improvement Project (ADB Assisted) | D2: Urban Development | E2: Urban Development | H2: Ongoing | I2: 105196.58 | J2: 18117.5 | K2: 0.05 | L2: Low | M2: 25 | N2: 5259.829 | O2: Institutional/reform programme - realistic minor MIS/digital & connectivity component | P2: Yes | Q2: Yes | Z2: KPK_ADP_2026-27_ICT_Opportunity.xlsx | AA2: ICT Projects
A3: KPK (Provincial ADP) | B3: 261278 | C3: Strengthening of Police, CTD , District Administration and Judiciary in Security Challenged Districts | D3: Home | E3: HTAs | H3: New | I3: 20000 | J3: 12000 | K3: 0.05 | L3: Low | M3: 600 | N3: 1000 | O3: Institutional/reform programme - realistic minor MIS/digital & connectivity component | P3: Yes | Q3: Yes | V3: Yes | X3: Yes | Z3: KPK_ADP_2026-27_ICT_Opportunity.xlsx | AA3: ICT Projects
A4: KPK (Provincial ADP) | B4: 220569 | C4: Khyber Pakhtunkhwa Health Strengthening Programme (SBS) for Revamping of Non-Teaching DHQ Hospital | D4: Health | E4: General Hospitals | H4: New | I4: 28000.003 | J4: 8700.001 | K4: 0.3 | L4: Medium | M4: 0.0003 | N4: 8400.0009 | O4: ICT-enabled: strengtheninghospitalhealth facilithealth informationsurveillance; Facility: bhospitalsb, bthqbbdhqbbrhcbbbhubbmchbcivil hospitals | P4: Yes | Q4: Yes | T4: Yes | V4: Yes | Z4: KPK_ADP_2026-27_ICT_Opportunity.xlsx | AA4: ICT Projects
A5: KPK (Provincial ADP) | B5: 200166 | C5: Refugees & Host Communities under IDA-18-Regional Sub Window SH: Khyber Pakhtunkhwa Human Capital Investment Project (KPHCIP) Education Component | D5: Elementary & Secondary Education | E5: E&SE Department | H5: Ongoing | I5: 32834.003 | J5: 8700.001 | K5: 0.05 | L5: Low | M5: 5e-05 | N5: 1641.7001 | O5: Institutional/reform programme - realistic minor MIS/digital & connectivity component | P5: Yes | Q5: Yes | Z5: KPK_ADP_2026-27_ICT_Opportunity.xlsx | AA5: ICT Projects
A6: KPK (Provincial ADP) | B6: 261146 | C6: Khyber Pakhtunkhwa Public Resource for Inclusive Development Multiphase programmatic Approach (KP-PRID-MPA) | D6: Finance | E6: Finance | H6: New | I6: 58000.003 | J6: 5800.001 | K6: 0.05 | L6: Low | M6: 5e-05 | N6: 2900.0001 | O6: Institutional/reform programme - realistic minor MIS/digital & connectivity component | P6: Yes | Q6: Yes | Z6: KPK_ADP_2026-27_ICT_Opportunity.xlsx | AA6: ICT Projects
A7: KPK (Provincial ADP) | B7: 210631 | C7: Khyber Pakhtunkhwa Rural Investment & Institutional Support Project (RIISP)(World Bank Assisted) | D7: Multi Sectoral Development | E7: MSD | H7: Ongoing | I7: 139698 | J7: 4467.7 | K7: 0.05 | L7: Low | M7: 5.885 | N7: 6984.9 | O7: Institutional/reform programme - realistic minor MIS/digital & connectivity component | P7: Yes | Q7: Yes | Z7: KPK_ADP_2026-27_ICT_Opportunity.xlsx | AA7: ICT Projects
A8: KPK (Provincial ADP) | B8: 170539 | C8: Khyber Pakhtunkhwa Integrated Tourism Development Project (KITE) (IDA Assisted) | D8: Tourism | E8: Tourism | H8: Ongoing | I8: 27303.804 | J8: 3000 | K8: 0.05 | L8: Low | M8: 5 | N8: 1365.1902 | O8: Institutional/reform programme - realistic minor MIS/digital & connectivity component | P8: Yes | Q8: Yes | Z8: KPK_ADP_2026-27_ICT_Opportunity.xlsx | AA8: ICT Projects
A9: KPK (Provincial ADP) | B9: 250870 | C9: Capacity Building and Development of Police and CTD Infrastructure in Merged Districts Phase-I | D9: Home | E9: Police | H9: Ongoing | I9: 8864.23 | J9: 2000 | K9: 0.05 | L9: Low | M9: 100 | N9: 443.2115 | O9: Institutional/reform programme - realistic minor MIS/digital & connectivity component | P9: Yes | Q9: Yes | V9: Yes | X9: Yes | Z9: KPK_ADP_2026-27_ICT_Opportunity.xlsx | AA9: ICT Projects
A10: KPK (Provincial ADP) | B10: 251564 | C10: Capacity Building and Development of Police and CTD Infrastructure in Merged Districts Phase-II | D10: Home | E10: Police | H10: Ongoing | I10: 7475.328 | J10: 2000 | K10: 0.05 | L10: Low | M10: 100 | N10: 373.7664 | O10: Institutional/reform programme - realistic minor MIS/digital & connectivity component | P10: Yes | Q10: Yes | V10: Yes | X10: Yes | Z10: KPK_ADP_2026-27_ICT_Opportunity.xlsx | AA10: ICT Projects
A11: KPK (Provincial ADP) | B11: 210287 | C11: Revamping of Secondary Health Facilities including Improvement of Accident and Emergency Units in Newly Merged Districts (AIP) | D11: Health | E11: General Hospitals | H11: Ongoing | I11: 7432.934 | J11: 1800 | K11: 0.05 | L11: Low | M11: 90 | N11: 371.6467 | O11: Facility: bhospitalsb, health facilityfacilitiescentrecenterunitcomplexcare | P11: Yes | Q11: Yes | V11: Yes | Z11: KPK_ADP_2026-27_ICT_Opportunity.xlsx | AA11: ICT Projects
A12: KPK (Provincial ADP) | B12: 210415 | C12: Khyber Pakhtunkhwa Spending Efficiently for Enhanced Development (SPEED) (IDA Assisted) | D12: Finance | E12: Finance | H12: Ongoing | I12: 112000 | J12: 1189.001 | K12: 0.05 | L12: Low | M12: 5e-05 | N12: 5600.0001 | O12: Institutional/reform programme - realistic minor MIS/digital & connectivity component | P12: Yes | Q12: Yes | Z12: KPK_ADP_2026-27_ICT_Opportunity.xlsx | AA12: ICT Projects
A13: KPK (Provincial ADP) | B13: 251629 | C13: Establishment of District Setup of Counter Terrorism Department at Khyber Pakhtunkhwa including construction of Peshawar Regional CTD Headquarters (Non-ADP) | D13: Home | E13: Police | H13: Ongoing | I13: 6441.34 | J13: 1008.14 | K13: 0.05 | L13: Low | M13: 50.407 | N13: 322.067 | O13: Facility: bofficesbbcomplexesbheadquartersecretariatdirectorate, establishment ofdepartmentauthoritycellunitwingofficedirectorateinstitute | P13: Yes | Q13: Yes | V13: Yes | X13: Yes | Z13: KPK_ADP_2026-27_ICT_Opportunity.xlsx | AA13: ICT Projects
A14: KPK (Provincial ADP) | B14: 210410 | C14: Institutional Development through innovative interventions | D14: Multi Sectoral Development | E14: Economic Infrastructural Development | H14: New | I14: 2000 | J14: 1000 | K14: 0.05 | L14: Low | M14: 50 | N14: 100 | O14: Institutional/reform programme - realistic minor MIS/digital & connectivity component | P14: Yes | Q14: Yes | Z14: KPK_ADP_2026-27_ICT_Opportunity.xlsx | AA14: ICT Projects
A15: KPK (Provincial ADP) | B15: 251628 | C15: Strengthening CTD's Mobility, Arms, Equipment and overall Modern Response Architecture (Non-ADP Approved) | D15: Home | E15: Police | H15: Ongoing | I15: 7770.34 | J15: 969.032 | K15: 0.05 | L15: Low | M15: 48.4516 | N15: 388.517 | O15: Institutional/reform programme - realistic minor MIS/digital & connectivity component | P15: Yes | Q15: Yes | V15: Yes | X15: Yes | Z15: KPK_ADP_2026-27_ICT_Opportunity.xlsx | AA15: ICT Projects
A16: KPK (Provincial ADP) | B16: 200197 | C16: Up-gradation of IRNUM PET-CT/Cyclotrom Project. | D16: Health | E16: General Hospitals | H16: Ongoing | I16: 2172.22 | J16: 900 | K16: 0.05 | L16: Low | M16: 45 | N16: 108.611 | O16: Facility: bhospitalsb | P16: Yes | Q16: Yes | V16: Yes | Z16: KPK_ADP_2026-27_ICT_Opportunity.xlsx | AA16: ICT Projects
A17: KPK (Provincial ADP) | B17: 210123 | C17: Strengthening of DHQ Hospitals (Building, Capacity to Respond Covid-19/any future Pandemic in Khyber Pakhtunkhwa (50% Provincial Share). | D17: Health | E17: General Hospitals | H17: Ongoing | I17: 8758.048 | J17: 890.667 | K17: 0.3 | L17: Medium | M17: 267.2001 | N17: 2627.4144 | O17: ICT-enabled: strengtheninghospitalhealth facilithealth informationsurveillance; Facility: bhospitalsb, bthqbbdhqbbrhcbbbhubbmchbcivil hospitals | P17: Yes | Q17: Yes | T17: Yes | V17: Yes | Z17: KPK_ADP_2026-27_ICT_Opportunity.xlsx | AA17: ICT Projects
A18: KPK (Provincial ADP) | B18: 240233 | C18: Establishment of Cath Labs at different hospitals of the Province on need basis | D18: Health | E18: General Hospitals | H18: Ongoing | I18: 1932.154 | J18: 800 | K18: 0.3 | L18: Medium | M18: 240 | N18: 579.6462 | O18: ICT-enabled: angiographycath labbmribbct scanb; Facility: bhospitalsb, establishmentuniversitycollegeschoolhospitalinstitutecenter | P18: Yes | Q18: Yes | T18: Yes | V18: Yes | Z18: KPK_ADP_2026-27_ICT_Opportunity.xlsx | AA18: ICT Projects
A19: KPK (Provincial ADP) | B19: 200049 | C19: Revamping of Non-Teaching DHQs across KP. | D19: Health | E19: General Hospitals | H19: Ongoing | I19: 7010.104 | J19: 799.999 | K19: 0.05 | L19: Low | M19: 39.99995 | N19: 350.5052 | O19: Facility: bhospitalsb | P19: Yes | Q19: Yes | V19: Yes | Z19: KPK_ADP_2026-27_ICT_Opportunity.xlsx | AA19: ICT Projects
A20: KPK (Provincial ADP) | B20: 210121 | C20: Strengthening of 12 DHQ Hospitals (Building Capacity to respond to Covid-19 / any future pandemic) in Khyber Pakhtunkhwa. (50% Provincial Share) | D20: Health | E20: General Hospitals | H20: Ongoing | I20: 9883.979 | J20: 780 | K20: 0.3 | L20: Medium | M20: 234 | N20: 2965.1937 | O20: ICT-enabled: strengtheninghospitalhealth facilithealth informationsurveillance; Facility: bhospitalsb, bthqbbdhqbbrhcbbbhubbmchbcivil hospitals | P20: Yes | Q20: Yes | T20: Yes | V20: Yes | Z20: KPK_ADP_2026-27_ICT_Opportunity.xlsx | AA20: ICT Projects
A21: KPK (Provincial ADP) | B21: 140150 | C21: Safe City Project Peshawar | D21: Home | E21: Police | H21: Ongoing | I21: 6974.79 | J21: 700 | K21: 0.7 | L21: High | M21: 490 | N21: 4882.353 | O21: Core-ICT: safe city | P21: Yes | Q21: Yes | R21: Yes | S21: Yes | T21: Yes | U21: Yes | V21: Yes | W21: Yes | X21: Yes | Z21: KPK_ADP_2026-27_ICT_Opportunity.xlsx | AA21: ICT Projects
A22: KPK (Provincial ADP) | B22: 260714 | C22: Establishment of Chief Minister Model Schools in Khyber Pakhtunkhwa (Phase-I) | D22: Elementary & Secondary Education | E22: E&SE Department | H22: New | I22: 6500 | J22: 700 | K22: 0.05 | L22: Low | M22: 35 | N22: 325 | O22: Facility: bschoolsb, establishment ofdepartmentauthoritycellunitwingofficedirectorateinstitute, establishmentuniversitycollegeschoolhospitalinstitutecenter | P22: Yes | Q22: Yes | V22: Yes | Z22: KPK_ADP_2026-27_ICT_Opportunity.xlsx | AA22: ICT Projects
A23: KPK (Provincial ADP) | B23: 251638 | C23: Establishment of Nursing College in the existing building of Regional Professional Development Centre (Female) at Jamrud Khyber | D23: Health | E23: Medical Education & Trg. | H23: Ongoing | I23: 635.487 | J23: 635.487 | K23: 0.05 | L23: Low | M23: 31.77435 | N23: 31.77435 | O23: Facility: bcollegesb, establishmentuniversitycollegeschoolhospitalinstitutecenter | P23: Yes | Q23: Yes | V23: Yes | Z23: KPK_ADP_2026-27_ICT_Opportunity.xlsx | AA23: ICT Projects
A24: KPK (Provincial ADP) | B24: 170331 | C24: Establishment of Forensic Science Laboratory (FSL) at Peshawar | D24: Home | E24: HTAs | H24: Ongoing | I24: 6887.64 | J24: 600 | K24: 0.05 | L24: Low | M24: 30 | N24: 344.382 | O24: Facility: bassemblybparliamentresearch stationinstitutecentercentreblaborator | P24: Yes | Q24: Yes | Z24: KPK_ADP_2026-27_ICT_Opportunity.xlsx | AA24: ICT Projects
A25: KPK (Provincial ADP) | B25: 150659 | C25: Institutional Support to P&D Department | D25: Multi Sectoral Development | E25: Research & Development | H25: Ongoing | I25: 2228 | J25: 591 | K25: 0.05 | L25: Low | M25: 29.55 | N25: 111.4 | O25: Institutional/reform programme - realistic minor MIS/digital & connectivity component | P25: Yes | Q25: Yes | Z25: KPK_ADP_2026-27_ICT_Opportunity.xlsx | AA25: ICT Projects
A26: KPK (Provincial ADP) | B26: 220154 | C26: Construction of District Judicial Complex Kohat | D26: Law & Justice | E26: Peshawar High Court | H26: Ongoing | I26: 1920.3 | J26: 560 | K26: 0.05 | L26: Low | M26: 28 | N26: 96.015 | O26: Facility: bofficesbbcomplexesbheadquartersecretariatdirectorate, bcourtsbjudicialjustice complex | P26: Yes | Q26: Yes | Z26: KPK_ADP_2026-27_ICT_Opportunity.xlsx | AA26: ICT Projects
A27: KPK (Provincial ADP) | B27: 260547 | C27: Establishment of Safe Cities at Divisional Headquarters (Kohat, Mardan / Mardan Package & Swat) | D27: Home | E27: Police | H27: New | I27: 3000 | J27: 500 | K27: 0.05 | L27: Low | M27: 25 | N27: 150 | O27: Facility: bofficesbbcomplexesbheadquartersecretariatdirectorate | P27: Yes | Q27: Yes | V27: Yes | X27: Yes | Z27: KPK_ADP_2026-27_ICT_Opportunity.xlsx | AA27: ICT Projects
A28: KPK (Provincial ADP) | B28: 150522 | C28: Establishment of Nowshera Medical College (Phase-I) | D28: Health | E28: Medical Education & Trg. | H28: Ongoing | I28: 2979.43 | J28: 500 | K28: 0.05 | L28: Low | M28: 25 | N28: 148.9715 | O28: Facility: bcollegesb, establishmentuniversitycollegeschoolhospitalinstitutecenter | P28: Yes | Q28: Yes | V28: Yes | Z28: KPK_ADP_2026-27_ICT_Opportunity.xlsx | AA28: ICT Projects
A29: KPK (Provincial ADP) | B29: 240004 | C29: Upgradation of Cat-D Hospital Sarwakai (Maula Khan Sari) to Cat-C Hospital Upper South Waziristan | D29: Health | E29: General Hospitals | H29: Ongoing | I29: 1200 | J29: 490 | K29: 0.05 | L29: Low | M29: 24.5 | N29: 60 | O29: Facility: bhospitalsb | P29: Yes | Q29: Yes | V29: Yes | Z29: KPK_ADP_2026-27_ICT_Opportunity.xlsx | AA29: ICT Projects
A30: KPK (Provincial ADP) | B30: 261235 | C30: Reconstruction / Rehabilitation of Fully Damaged Schools in District Khyber under Chinese Assistance Programme (Saving under ADP No. 191268/190280) | D30: Elementary & Secondary Education | E30: Foreign Assistance | H30: New | I30: 592.078 | J30: 487.201 | K30: 0.05 | L30: Low | M30: 5e-05 | N30: 29.6039 | O30: Facility: bschoolsb | P30: Yes | Q30: Yes | V30: Yes | Z30: KPK_ADP_2026-27_ICT_Opportunity.xlsx | AA30: ICT Projects
A31: KPK (Provincial ADP) | B31: 220650 | C31: Digitization (e-Governance) of Khyber Pakhtunkhwa (KFW Assisted) | D31: Science Technology & Information Technology | E31: Information Technology Board (KPITB) | H31: New | I31: 5110 | J31: 440 | K31: 0.7 | L31: High | M31: 3.5 | N31: 3577 | O31: Core-ICT: e-gov, digitiszation, information technology | P31: Yes | Q31: Yes | R31: Yes | S31: Yes | T31: Yes | U31: Yes | Z31: KPK_ADP_2026-27_ICT_Opportunity.xlsx | AA31: ICT Projects
A32: KPK (Provincial ADP) | B32: 210676 | C32: Up-gradation of Research Institutes to the Centers of Excellence. | D32: Agriculture | E32: Agriculture Research Systems | H32: Ongoing | I32: 1729.969 | J32: 423.269 | K32: 0.05 | L32: Low | M32: 21.16345 | N32: 86.49845 | O32: Facility: binstitutesb, bassemblybparliamentresearch stationinstitutecentercentreblaborator | P32: Yes | Q32: Yes | Z32: KPK_ADP_2026-27_ICT_Opportunity.xlsx | AA32: ICT Projects
A33: KPK (Provincial ADP) | B33: 210286 | C33: Provision of Express Lines to Cat-D Hospitals in Merged Areas (AIP). | D33: Health | E33: General Hospitals | H33: Ongoing | I33: 685.76 | J33: 423.268 | K33: 0.05 | L33: Low | M33: 21.1634 | N33: 34.288 | O33: Facility: bhospitalsb | P33: Yes | Q33: Yes | V33: Yes | Z33: KPK_ADP_2026-27_ICT_Opportunity.xlsx | AA33: ICT Projects
A34: KPK (Provincial ADP) | B34: 210493 | C34: Establishment of 67 ( 30:70 B&G) Primary Schools in Khyber Pakhtunkhwa | D34: Elementary & Secondary Education | E34: Primary Education | H34: Ongoing | I34: 740.347 | J34: 417.457 | K34: 0.05 | L34: Low | M34: 20.87285 | N34: 37.01735 | O34: Facility: bschoolsb, establishmentuniversitycollegeschoolhospitalinstitutecenter | P34: Yes | Q34: Yes | V34: Yes | Z34: KPK_ADP_2026-27_ICT_Opportunity.xlsx | AA34: ICT Projects
A35: KPK (Provincial ADP) | B35: 160187 | C35: Construction of Judicial Complexes, Swat | D35: Law & Justice | E35: Peshawar High Court | H35: Ongoing | I35: 1803.38 | J35: 407.976 | K35: 0.05 | L35: Low | M35: 20.3988 | N35: 90.169 | O35: Facility: bofficesbbcomplexesbheadquartersecretariatdirectorate, bcourtsbjudicialjustice complex | P35: Yes | Q35: Yes | Z35: KPK_ADP_2026-27_ICT_Opportunity.xlsx | AA35: ICT Projects
A36: KPK (Provincial ADP) | B36: 160595 | C36: Upgradation of 50 High Schools to Higher Secondary level (B&G) on need basis in Khyber Pakhtunkhwa (less 18 units) | D36: Elementary & Secondary Education | E36: Secondary Education | H36: Ongoing | I36: 1207.761 | J36: 405.311 | K36: 0.05 | L36: Low | M36: 20.26555 | N36: 60.38805 | O36: Facility: bschoolsb | P36: Yes | Q36: Yes | V36: Yes | Z36: KPK_ADP_2026-27_ICT_Opportunity.xlsx | AA36: ICT Projects
A37: KPK (Provincial ADP) | B37: 191400 | C37: Construction of Examination Halls in Schools on Need Basis (AIP) | D37: Elementary & Secondary Education | E37: Secondary Education | H37: Ongoing | I37: 1079.939 | J37: 400 | K37: 0.05 | L37: Low | M37: 20 | N37: 53.99695 | O37: Facility: bschoolsb | P37: Yes | Q37: Yes | V37: Yes | Z37: KPK_ADP_2026-27_ICT_Opportunity.xlsx | AA37: ICT Projects
A38: KPK (Provincial ADP) | B38: 250508 | C38: Construction of boys Hostels at Kohat Institute of Medical Sciences (KIMS), Kohat | D38: Health | E38: Medical Education & Trg. | H38: Ongoing | I38: 687.69 | J38: 400 | K38: 0.05 | L38: Low | M38: 20 | N38: 34.3845 | O38: Facility: binstitutesb, bhostelsb | P38: Yes | Q38: Yes | Z38: KPK_ADP_2026-27_ICT_Opportunity.xlsx | AA38: ICT Projects
A39: KPK (Provincial ADP) | B39: 200138 | C39: Provision of Additional infrastructure and repair of existing colleges | D39: Higher Education | E39: College Education | H39: Ongoing | I39: 1178.58 | J39: 392.98 | K39: 0.05 | L39: Low | M39: 19.649 | N39: 58.929 | O39: Facility: bcollegesb | P39: Yes | Q39: Yes | V39: Yes | Z39: KPK_ADP_2026-27_ICT_Opportunity.xlsx | AA39: ICT Projects
A40: KPK (Provincial ADP) | B40: 140813 | C40: Upgradation of Booni Hospital to Category-C Hospital, District Chitral. | D40: Health | E40: General Hospitals | H40: Ongoing | I40: 1083.955 | J40: 385.968 | K40: 0.05 | L40: Low | M40: 19.2984 | N40: 54.19775 | O40: Facility: bhospitalsb | P40: Yes | Q40: Yes | V40: Yes | Z40: KPK_ADP_2026-27_ICT_Opportunity.xlsx | AA40: ICT Projects
...

Sheet Region Summary
A1: Region | B1: Project Count | C1: Total FY2026-27 Allocation (M PKR) | D1: Total ICT TAM on Allocation (M PKR)
A2: KPK (Provincial ADP) | B2: =COUNTIF('ICT Projects - Consolidated'!A2:A2555,A2) | C2: =SUMIF('ICT Projects - Consolidated'!A2:A2555,A2,'ICT Projects - Consolidated'!J2:J2555) | D2: =SUMIF('ICT Projects - Consolidated'!A2:A2555,A2,'ICT Projects - Consolidated'!M2:M2555)
A3: Sindh (Provincial ADP) | B3: =COUNTIF('ICT Projects - Consolidated'!A2:A2555,A3) | C3: =SUMIF('ICT Projects - Consolidated'!A2:A2555,A3,'ICT Projects - Consolidated'!J2:J2555) | D3: =SUMIF('ICT Projects - Consolidated'!A2:A2555,A3,'ICT Projects - Consolidated'!M2:M2555)
A4: Federal (PSDP) | B4: =COUNTIF('ICT Projects - Consolidated'!A2:A2555,A4) | C4: =SUMIF('ICT Projects - Consolidated'!A2:A2555,A4,'ICT Projects - Consolidated'!J2:J2555) | D4: =SUMIF('ICT Projects - Consolidated'!A2:A2555,A4,'ICT Projects - Consolidated'!M2:M2555)
A5: Balochistan (Provincial PSDP) | B5: =COUNTIF('ICT Projects - Consolidated'!A2:A2555,A5) | C5: =SUMIF('ICT Projects - Consolidated'!A2:A2555,A5,'ICT Projects - Consolidated'!J2:J2555) | D5: =SUMIF('ICT Projects - Consolidated'!A2:A2555,A5,'ICT Projects - Consolidated'!M2:M2555)
A6: Punjab (Provincial ADP) | B6: =COUNTIF('ICT Projects - Consolidated'!A2:A2555,A6) | C6: =SUMIF('ICT Projects - Consolidated'!A2:A2555,A6,'ICT Projects - Consolidated'!J2:J2555) | D6: =SUMIF('ICT Projects - Consolidated'!A2:A2555,A6,'ICT Projects - Consolidated'!M2:M2555)
A7: TOTAL | B7: =SUM(B2:B6) | C7: =SUM(C2:C6) | D7: =SUM(D2:D6)

Sheet Project News
A1: Project ID | B1: Project Name | C1: News Date | D1: News Title | E1: Keypoints | F1: Source | G1: URL | H1: Last Updated
A88: 210631 | B88: Khyber Pakhtunkhwa Rural Investment & Institutional Support Project (RIISP)(World Bank Assisted) | D88: Rural Investment and Institutional Support Project (RIISP) ... | E88: - GoKP requests $300 m IDA Credit from World Bank for rural investment and institutional support. - Funding aims to boost rural development and strengthen local institutions. | F88: kppra.gov.pk | G88: http://www.kppra.gov.pk/kppra/staff/force_download.php?file=dept%2Fupload%2F1705324703TORsandIrrigationandKPRIISPandFinal.pdf | H88: 46276.508
A89: 210631 | B89: Khyber Pakhtunkhwa Rural Investment & Institutional Support Project (RIISP)(World Bank Assisted) | D89: khyber pakhtunkhwa rural investment and institutional ... | E89: - World Bank funds $330 M Khyber Pakhtunkhwa Rural Investment Project to strengthen local institutions. - Project targets 4.5–5.5 million residents, building infrastructure in agriculture, water, roads, sanitation. | F89: documents1.worldbank.org | G89: https://documents1.worldbank.org/curated/en/099805312232218100/pdf/P1767800bb13ee050b40f0e1eee87aabc2.pdf | H89: 46276.508
A90: 210631 | B90: Khyber Pakhtunkhwa Rural Investment & Institutional Support Project (RIISP)(World Bank Assisted) | D90: Pakistan: World Bank Approves $200 million in support of Citizen-Driven Rural Investments and Post-Floods Rehabilitation for Khyber Pakhtunkhwa Province - Pakistan | ReliefWeb | E90: - World Bank approves $200 M for KPRIISP first phase, targeting 5.5 million rural households. - Project will rehabilitate flood damage, empower village councils, and strengthen service delivery. | F90: reliefweb.int | G90: https://reliefweb.int/report/pakistan/pakistan-world-bank-approves-200-million-support-citizen-driven-rural-investments-and-post-floods-rehabilitation-khyber-pakhtunkhwa-province | H90: 46276.508
A91: 210631 | B91: Khyber Pakhtunkhwa Rural Investment & Institutional Support Project (RIISP)(World Bank Assisted) | D91: + KP-Rural Investment and Institutional Support Project - “Governance Through Excellence” | E91: - Project on track: infrastructure rehabilitation, budget disbursement, safeguards, and community engagement progressing. - Modern tunnel farming delivers high‑quality vegetables, boosting farmer incomes and local markets. | F91: linkedin.com | G91: https://www.linkedin.com/company/kp-rural-investment-and-institutional-support-project | H91: 46276.508
A92: 210631 | B92: Khyber Pakhtunkhwa Rural Investment & Institutional Support Project (RIISP)(World Bank Assisted) | D92: Khyber Pakhtunkhwa Rural... - Contractor & Builders | E92: - Invitation for bids to rehabilitate solarized water schemes in Khyber district; deadline Oct 2026. - Project cost 70.053 M PKR, funded by World Bank IDA, using national competitive bidding. | F92: facebook.com | G92: https://www.facebook.com/100083372700792/posts/khyber-pakhtunkhwa-rural-investment-and-institutional-support-project/1095975029858244 | H92: 46276.508
A93: 210631 | B93: Khyber Pakhtunkhwa Rural Investment & Institutional Support Project (RIISP)(World Bank Assisted) | D93: government of khyber pakhtunkhwa | E93: - Project covers 14 districts, spans nine years with two four‑year phases under MPA. - Resettlement framework prepared to manage land acquisition, restrictions, and involuntary resettlement, supporting climate resilience. | F93: documents1.worldbank.org | G93: https://documents1.worldbank.org/curated/en/099041823174032123/pdf/P17678007e538b0e0804b0fd277ad94e7f.pdf | H93: 46276.508
A94: 210631 | B94: Khyber Pakhtunkhwa Rural Investment & Institutional Support Project (RIISP)(World Bank Assisted) | D94: Early Warning System | E94: - Expanding state services in merged Khyber Pakhtunkhwa areas via infrastructure and delivery system investments. - Strengthening local governance, flood protection, and project management through institutional support and capacity building. | F94: ewsdata.rightsindevelopment.org | G94: https://ewsdata.rightsindevelopment.org/projects/p176780-khyber-pakhtunkhwa-rural-investment-and-institutio | H94: 46276.508
A95: 210631 | B95: Khyber Pakhtunkhwa Rural Investment & Institutional Support Project (RIISP)(World Bank Assisted) | D95: World Bank's $200M Rural Investment Project in Khyber ... | E95: - World Bank funds $200M rural investment in Khyber Pakhtunkhwa. - Project gaining steady momentum. | F95: linkedin.com | G95: https://www.linkedin.com/posts/pakbanker_world-banks-200m-kp-rural-investment-project-activity-7441825411992276992-4h1Z | H95: 46276.508
A96: 210631 | B96: Khyber Pakhtunkhwa Rural Investment & Institutional Support Project (RIISP)(World Bank Assisted) | D96: A Meeting With The World Bank Mission Regarding KP-RIISP | E96: - Meeting with World Bank Mission held. - No project updates disclosed. | F96: pndkp.gov.pk | G96: https://pndkp.gov.pk/2025/12/05/a-meeting-with-the-world-bank-mission-regarding-kp-riisp | H96: 46276.508
A97: 210631 | B97: Khyber Pakhtunkhwa Rural Investment & Institutional Support Project (RIISP)(World Bank Assisted) | D97: Project Information Document - Khyber Pakhtunkhwa Rural Investment and Institutional Support Project - P176780 | E97: - No new project updates provided. - Project status remains unchanged. | F97: documents.worldbank.org | G97: https://documents.worldbank.org/en/publication/documents-reports/documentdetail/099042823082039352 | H97: 46276.508
